<mujoco>
  <asset>
    <texture name="grid" type="2d" builtin="checker" rgb1=".1 .2 .3"
     rgb2=".2 .3 .4" width="300" height="300"/>
    <material name="grid" texture="grid" texrepeat="8 8" reflectance=".2"/>
  </asset>

  <worldbody>
    <geom size="2 2 .01" type="plane" material="grid"/>
    <light pos="0 0 .6"/>
	<body name="spin_box" pos="0 0 .02">
		<joint name="spin_joint" type="hinge" axis="0 0 1"/>
		<geom name="red_box" type="box" size=".02 .02 .02" rgba=".5 1 .5 1"/>
	</body>
	<body name="slide_box" pos=".1 .1 .02">
		<joint name="slide_joint" type="slide" axis="0 1 0"/>
		<geom name="orange_box" type="box" size=".02 .02 .02" rgba="1 .5 .5 1"/>
	</body>
  </worldbody>
    <actuator>
        <!-- Add a general force actuator to apply torque to the joint -->
        <general name="spinner" joint="spin_joint" ctrlrange="-1 1"/>
        <general name="slider" joint="slide_joint" ctrlrange="-1 1"/>
    </actuator>

</mujoco>
